<?xml version="1.0"?>
<robot name="/home/oscar/Robotino3.urdf" xmlns:xacro="http://ros.org/wiki/xacro">
  <link name="base_link">
    <visual>
      <origin xyz="0.01 0 0" rpy="0 0 1.5708"/>
      <geometry>
        <mesh filename="package://rto_description/meshes/parts/robotino_base.dae" scale="0.01 0.01 0.01"/>
      </geometry>
    </visual>
    <collision>
      <origin xyz="0 0 0.153" rpy="0 0 0"/>
      <geometry>
        <cylinder radius="0.2266" length="0.276"/>
      </geometry>
    </collision>
  </link>
  <link name="cap screw(6)">
    <visual>
      <origin xyz="0.005 0 0" rpy="3.141593 1.570793 3.141593"/>
      <geometry>
        <cylinder radius="0.0018" length="0.01"/>
      </geometry>
    </visual>
    <collision>
      <origin xyz="0.005 0 0" rpy="3.141593 1.570793 3.141593"/>
      <geometry>
        <cylinder radius="0.0018" length="0.01"/>
      </geometry>
    </collision>
    <visual>
      <origin xyz="-0.0018 0 0" rpy="3.141593 1.570793 3.141593"/>
      <geometry>
        <cylinder radius="0.003" length="0.0036"/>
      </geometry>
    </visual>
    <collision>
      <origin xyz="-0.0018 0 0" rpy="3.141593 1.570793 3.141593"/>
      <geometry>
        <cylinder radius="0.003" length="0.0036"/>
      </geometry>
    </collision>
  </link>
  <joint name="base_link_cap screw(6)_joint" type="fixed">
    <parent link="base_link"/>
    <child link="cap screw(6)"/>
    <origin xyz="0.1097 0.189 0.092" rpy="0.000008 -0.000002 -2.094393"/>
  </joint>
  <link name="cap screw(5)">
    <visual>
      <origin xyz="0.005 0 0" rpy="3.141593 1.570793 3.141593"/>
      <geometry>
        <cylinder radius="0.0018" length="0.01"/>
      </geometry>
    </visual>
    <collision>
      <origin xyz="0.005 0 0" rpy="3.141593 1.570793 3.141593"/>
      <geometry>
        <cylinder radius="0.0018" length="0.01"/>
      </geometry>
    </collision>
    <visual>
      <origin xyz="-0.0018 0 0" rpy="3.141593 1.570793 3.141593"/>
      <geometry>
        <cylinder radius="0.003" length="0.0036"/>
      </geometry>
    </visual>
    <collision>
      <origin xyz="-0.0018 0 0" rpy="3.141593 1.570793 3.141593"/>
      <geometry>
        <cylinder radius="0.003" length="0.0036"/>
      </geometry>
    </collision>
  </link>
  <joint name="base_link_cap screw(5)_joint" type="fixed">
    <parent link="base_link"/>
    <child link="cap screw(5)"/>
    <origin xyz="0.1097 -0.189 0.092" rpy="0.000002 0.000003 2.094393"/>
  </joint>
  <link name="cap screw(4)">
    <visual>
      <origin xyz="0.005 0 0" rpy="3.141593 1.570793 3.141593"/>
      <geometry>
        <cylinder radius="0.0018" length="0.01"/>
      </geometry>
    </visual>
    <collision>
      <origin xyz="0.005 0 0" rpy="3.141593 1.570793 3.141593"/>
      <geometry>
        <cylinder radius="0.0018" length="0.01"/>
      </geometry>
    </collision>
    <visual>
      <origin xyz="-0.0018 0 0" rpy="3.141593 1.570793 3.141593"/>
      <geometry>
        <cylinder radius="0.003" length="0.0036"/>
      </geometry>
    </visual>
    <collision>
      <origin xyz="-0.0018 0 0" rpy="3.141593 1.570793 3.141593"/>
      <geometry>
        <cylinder radius="0.003" length="0.0036"/>
      </geometry>
    </collision>
  </link>
  <joint name="base_link_cap screw(4)_joint" type="fixed">
    <parent link="base_link"/>
    <child link="cap screw(4)"/>
    <origin xyz="-0.0372 -0.207 0.213" rpy="0 0 1.570796"/>
  </joint>
  <link name="cap screw(3)">
    <visual>
      <origin xyz="0.005 0 0" rpy="3.141593 1.570793 3.141593"/>
      <geometry>
        <cylinder radius="0.0018" length="0.01"/>
      </geometry>
    </visual>
    <collision>
      <origin xyz="0.005 0 0" rpy="3.141593 1.570793 3.141593"/>
      <geometry>
        <cylinder radius="0.0018" length="0.01"/>
      </geometry>
    </collision>
    <visual>
      <origin xyz="-0.0018 0 0" rpy="3.141593 1.570793 3.141593"/>
      <geometry>
        <cylinder radius="0.003" length="0.0036"/>
      </geometry>
    </visual>
    <collision>
      <origin xyz="-0.0018 0 0" rpy="3.141593 1.570793 3.141593"/>
      <geometry>
        <cylinder radius="0.003" length="0.0036"/>
      </geometry>
    </collision>
  </link>
  <joint name="base_link_cap screw(3)_joint" type="fixed">
    <parent link="base_link"/>
    <child link="cap screw(3)"/>
    <origin xyz="-0.0372 0.207 0.213" rpy="3.141593 0.000008 -1.570796"/>
  </joint>
  <link name="cap screw(2)">
    <visual>
      <origin xyz="0.005 0 0" rpy="3.141593 1.570793 3.141593"/>
      <geometry>
        <cylinder radius="0.0018" length="0.01"/>
      </geometry>
    </visual>
    <collision>
      <origin xyz="0.005 0 0" rpy="3.141593 1.570793 3.141593"/>
      <geometry>
        <cylinder radius="0.0018" length="0.01"/>
      </geometry>
    </collision>
    <visual>
      <origin xyz="-0.0018 0 0" rpy="3.141593 1.570793 3.141593"/>
      <geometry>
        <cylinder radius="0.003" length="0.0036"/>
      </geometry>
    </visual>
    <collision>
      <origin xyz="-0.0018 0 0" rpy="3.141593 1.570793 3.141593"/>
      <geometry>
        <cylinder radius="0.003" length="0.0036"/>
      </geometry>
    </collision>
  </link>
  <joint name="base_link_cap screw(2)_joint" type="fixed">
    <parent link="base_link"/>
    <child link="cap screw(2)"/>
    <origin xyz="-0.2183 0 0.092" rpy="1.570796 0.000003 -0.000003"/>
  </joint>
  <link name="cap screw(1)">
    <visual>
      <origin xyz="0.005 0 0" rpy="3.141593 1.570793 3.141593"/>
      <geometry>
        <cylinder radius="0.0018" length="0.01"/>
      </geometry>
    </visual>
    <collision>
      <origin xyz="0.005 0 0" rpy="3.141593 1.570793 3.141593"/>
      <geometry>
        <cylinder radius="0.0018" length="0.01"/>
      </geometry>
    </collision>
    <visual>
      <origin xyz="-0.0018 0 0" rpy="3.141593 1.570793 3.141593"/>
      <geometry>
        <cylinder radius="0.003" length="0.0036"/>
      </geometry>
    </visual>
    <collision>
      <origin xyz="-0.0018 0 0" rpy="3.141593 1.570793 3.141593"/>
      <geometry>
        <cylinder radius="0.003" length="0.0036"/>
      </geometry>
    </collision>
  </link>
  <joint name="base_link_cap screw(1)_joint" type="fixed">
    <parent link="base_link"/>
    <child link="cap screw(1)"/>
    <origin xyz="-0.194 0.08 0.213" rpy="-1.662276 -0.01634 -0.353273"/>
  </joint>
  <link name="cap screw">
    <visual>
      <origin xyz="0.005 0 0" rpy="3.141593 1.570793 3.141593"/>
      <geometry>
        <cylinder radius="0.0018" length="0.01"/>
      </geometry>
    </visual>
    <collision>
      <origin xyz="0.005 0 0" rpy="3.141593 1.570793 3.141593"/>
      <geometry>
        <cylinder radius="0.0018" length="0.01"/>
      </geometry>
    </collision>
    <visual>
      <origin xyz="-0.0018 0 0" rpy="3.141593 1.570793 3.141593"/>
      <geometry>
        <cylinder radius="0.003" length="0.0036"/>
      </geometry>
    </visual>
    <collision>
      <origin xyz="-0.0018 0 0" rpy="3.141593 1.570793 3.141593"/>
      <geometry>
        <cylinder radius="0.003" length="0.0036"/>
      </geometry>
    </collision>
  </link>
  <joint name="base_link_cap screw_joint" type="fixed">
    <parent link="base_link"/>
    <child link="cap screw"/>
    <origin xyz="-0.194 -0.08 0.213" rpy="-1.479317 -0.01634 0.35328"/>
  </joint>
  <link name="touch sensor">
  </link>
  <joint name="base_link_touch sensor_joint" type="fixed">
    <parent link="base_link"/>
    <child link="touch sensor"/>
    <origin xyz="0 0 0.035" rpy="0 0 1.570796"/>
  </joint>
  <link name="ir9">
    <visual>
      <origin xyz="-0.0052 -0.0102 0" rpy="0 0 0"/>
      <geometry>
        <box size="0.01 0.03 0.0087"/>
      </geometry>
    </visual>
    <collision>
      <origin xyz="-0.0052 -0.0102 0" rpy="0 0 0"/>
      <geometry>
        <box size="0.01 0.03 0.0087"/>
      </geometry>
    </collision>
    <visual>
      <origin xyz="-0.0109 -0.0102 0" rpy="0 0 0"/>
      <geometry>
        <box size="0.0094 0.03 0.0131"/>
      </geometry>
    </visual>
    <collision>
      <origin xyz="-0.0109 -0.0102 0" rpy="0 0 0"/>
      <geometry>
        <box size="0.0094 0.03 0.0131"/>
      </geometry>
    </collision>
    <visual>
      <origin xyz="-0.0144 -0.0102 0" rpy="0 0 0"/>
      <geometry>
        <box size="0.0023 0.0445 0.0077"/>
      </geometry>
    </visual>
    <collision>
      <origin xyz="-0.0144 -0.0102 0" rpy="0 0 0"/>
      <geometry>
        <box size="0.0023 0.0445 0.0077"/>
      </geometry>
    </collision>
  </link>
  <joint name="base_link_ir9_joint" type="fixed">
    <parent link="base_link"/>
    <child link="ir9"/>
    <origin xyz="0.1735 -0.1455 0.0566" rpy="1.570796 0 -0.639973"/>
  </joint>
  <link name="ir8">
    <visual>
      <origin xyz="-0.0052 -0.0102 0" rpy="0 0 0"/>
      <geometry>
        <box size="0.01 0.03 0.0087"/>
      </geometry>
    </visual>
    <collision>
      <origin xyz="-0.0052 -0.0102 0" rpy="0 0 0"/>
      <geometry>
        <box size="0.01 0.03 0.0087"/>
      </geometry>
    </collision>
    <visual>
      <origin xyz="-0.0109 -0.0102 0" rpy="0 0 0"/>
      <geometry>
        <box size="0.0094 0.03 0.0131"/>
      </geometry>
    </visual>
    <collision>
      <origin xyz="-0.0109 -0.0102 0" rpy="0 0 0"/>
      <geometry>
        <box size="0.0094 0.03 0.0131"/>
      </geometry>
    </collision>
    <visual>
      <origin xyz="-0.0144 -0.0102 0" rpy="0 0 0"/>
      <geometry>
        <box size="0.0023 0.0445 0.0077"/>
      </geometry>
    </visual>
    <collision>
      <origin xyz="-0.0144 -0.0102 0" rpy="0 0 0"/>
      <geometry>
        <box size="0.0023 0.0445 0.0077"/>
      </geometry>
    </collision>
  </link>
  <joint name="base_link_ir8_joint" type="fixed">
    <parent link="base_link"/>
    <child link="ir8"/>
    <origin xyz="0.0394 -0.2229 0.0566" rpy="1.570796 0 -1.3381"/>
  </joint>
  <link name="ir7">
    <visual>
      <origin xyz="-0.0052 -0.0102 0" rpy="0 0 0"/>
      <geometry>
        <box size="0.01 0.03 0.0087"/>
      </geometry>
    </visual>
    <collision>
      <origin xyz="-0.0052 -0.0102 0" rpy="0 0 0"/>
      <geometry>
        <box size="0.01 0.03 0.0087"/>
      </geometry>
    </collision>
    <visual>
      <origin xyz="-0.0109 -0.0102 0" rpy="0 0 0"/>
      <geometry>
        <box size="0.0094 0.03 0.0131"/>
      </geometry>
    </visual>
    <collision>
      <origin xyz="-0.0109 -0.0102 0" rpy="0 0 0"/>
      <geometry>
        <box size="0.0094 0.03 0.0131"/>
      </geometry>
    </collision>
    <visual>
      <origin xyz="-0.0144 -0.0102 0" rpy="0 0 0"/>
      <geometry>
        <box size="0.0023 0.0445 0.0077"/>
      </geometry>
    </visual>
    <collision>
      <origin xyz="-0.0144 -0.0102 0" rpy="0 0 0"/>
      <geometry>
        <box size="0.0023 0.0445 0.0077"/>
      </geometry>
    </collision>
  </link>
  <joint name="base_link_ir7_joint" type="fixed">
    <parent link="base_link"/>
    <child link="ir7"/>
    <origin xyz="-0.1133 -0.196 0.0566" rpy="1.570797 -0.000001 -2.036229"/>
  </joint>
  <link name="ir6">
    <visual>
      <origin xyz="-0.0052 -0.0102 0" rpy="0 0 0"/>
      <geometry>
        <box size="0.01 0.03 0.0087"/>
      </geometry>
    </visual>
    <collision>
      <origin xyz="-0.0052 -0.0102 0" rpy="0 0 0"/>
      <geometry>
        <box size="0.01 0.03 0.0087"/>
      </geometry>
    </collision>
    <visual>
      <origin xyz="-0.0109 -0.0102 0" rpy="0 0 0"/>
      <geometry>
        <box size="0.0094 0.03 0.0131"/>
      </geometry>
    </visual>
    <collision>
      <origin xyz="-0.0109 -0.0102 0" rpy="0 0 0"/>
      <geometry>
        <box size="0.0094 0.03 0.0131"/>
      </geometry>
    </collision>
    <visual>
      <origin xyz="-0.0144 -0.0102 0" rpy="0 0 0"/>
      <geometry>
        <box size="0.0023 0.0445 0.0077"/>
      </geometry>
    </visual>
    <collision>
      <origin xyz="-0.0144 -0.0102 0" rpy="0 0 0"/>
      <geometry>
        <box size="0.0023 0.0445 0.0077"/>
      </geometry>
    </collision>
  </link>
  <joint name="base_link_ir6_joint" type="fixed">
    <parent link="base_link"/>
    <child link="ir6"/>
    <origin xyz="-0.2133 -0.0772 0.0566" rpy="1.570796 0 -2.734369"/>
  </joint>
  <link name="ir5">
    <visual>
      <origin xyz="-0.0052 -0.0102 0" rpy="0 0 0"/>
      <geometry>
        <box size="0.01 0.03 0.0087"/>
      </geometry>
    </visual>
    <collision>
      <origin xyz="-0.0052 -0.0102 0" rpy="0 0 0"/>
      <geometry>
        <box size="0.01 0.03 0.0087"/>
      </geometry>
    </collision>
    <visual>
      <origin xyz="-0.0109 -0.0102 0" rpy="0 0 0"/>
      <geometry>
        <box size="0.0094 0.03 0.0131"/>
      </geometry>
    </visual>
    <collision>
      <origin xyz="-0.0109 -0.0102 0" rpy="0 0 0"/>
      <geometry>
        <box size="0.0094 0.03 0.0131"/>
      </geometry>
    </collision>
    <visual>
      <origin xyz="-0.0144 -0.0102 0" rpy="0 0 0"/>
      <geometry>
        <box size="0.0023 0.0445 0.0077"/>
      </geometry>
    </visual>
    <collision>
      <origin xyz="-0.0144 -0.0102 0" rpy="0 0 0"/>
      <geometry>
        <box size="0.0023 0.0445 0.0077"/>
      </geometry>
    </collision>
  </link>
  <joint name="base_link_ir5_joint" type="fixed">
    <parent link="base_link"/>
    <child link="ir5"/>
    <origin xyz="-0.2131 0.0777 0.0566" rpy="1.570796 0 2.850685"/>
  </joint>
  <link name="ir4">
    <visual>
      <origin xyz="-0.0052 -0.0102 0" rpy="0 0 0"/>
      <geometry>
        <box size="0.01 0.03 0.0087"/>
      </geometry>
    </visual>
    <collision>
      <origin xyz="-0.0052 -0.0102 0" rpy="0 0 0"/>
      <geometry>
        <box size="0.01 0.03 0.0087"/>
      </geometry>
    </collision>
    <visual>
      <origin xyz="-0.0109 -0.0102 0" rpy="0 0 0"/>
      <geometry>
        <box size="0.0094 0.03 0.0131"/>
      </geometry>
    </visual>
    <collision>
      <origin xyz="-0.0109 -0.0102 0" rpy="0 0 0"/>
      <geometry>
        <box size="0.0094 0.03 0.0131"/>
      </geometry>
    </collision>
    <visual>
      <origin xyz="-0.0144 -0.0102 0" rpy="0 0 0"/>
      <geometry>
        <box size="0.0023 0.0445 0.0077"/>
      </geometry>
    </visual>
    <collision>
      <origin xyz="-0.0144 -0.0102 0" rpy="0 0 0"/>
      <geometry>
        <box size="0.0023 0.0445 0.0077"/>
      </geometry>
    </collision>
  </link>
  <joint name="base_link_ir4_joint" type="fixed">
    <parent link="base_link"/>
    <child link="ir4"/>
    <origin xyz="-0.114 0.1963 0.0566" rpy="1.570796 0 2.152557"/>
  </joint>
  <link name="ir3">
    <visual>
      <origin xyz="-0.0052 -0.0102 0" rpy="0 0 0"/>
      <geometry>
        <box size="0.01 0.03 0.0087"/>
      </geometry>
    </visual>
    <collision>
      <origin xyz="-0.0052 -0.0102 0" rpy="0 0 0"/>
      <geometry>
        <box size="0.01 0.03 0.0087"/>
      </geometry>
    </collision>
    <visual>
      <origin xyz="-0.0109 -0.0102 0" rpy="0 0 0"/>
      <geometry>
        <box size="0.0094 0.03 0.0131"/>
      </geometry>
    </visual>
    <collision>
      <origin xyz="-0.0109 -0.0102 0" rpy="0 0 0"/>
      <geometry>
        <box size="0.0094 0.03 0.0131"/>
      </geometry>
    </collision>
    <visual>
      <origin xyz="-0.0144 -0.0102 0" rpy="0 0 0"/>
      <geometry>
        <box size="0.0023 0.0445 0.0077"/>
      </geometry>
    </visual>
    <collision>
      <origin xyz="-0.0144 -0.0102 0" rpy="0 0 0"/>
      <geometry>
        <box size="0.0023 0.0445 0.0077"/>
      </geometry>
    </collision>
  </link>
  <joint name="base_link_ir3_joint" type="fixed">
    <parent link="base_link"/>
    <child link="ir3"/>
    <origin xyz="0.0394 0.223 0.0566" rpy="1.570796 0 1.454421"/>
  </joint>
  <link name="ir2">
    <visual>
      <origin xyz="-0.0052 -0.0102 0" rpy="0 0 0"/>
      <geometry>
        <box size="0.01 0.03 0.0087"/>
      </geometry>
    </visual>
    <collision>
      <origin xyz="-0.0052 -0.0102 0" rpy="0 0 0"/>
      <geometry>
        <box size="0.01 0.03 0.0087"/>
      </geometry>
    </collision>
    <visual>
      <origin xyz="-0.0109 -0.0102 0" rpy="0 0 0"/>
      <geometry>
        <box size="0.0094 0.03 0.0131"/>
      </geometry>
    </visual>
    <collision>
      <origin xyz="-0.0109 -0.0102 0" rpy="0 0 0"/>
      <geometry>
        <box size="0.0094 0.03 0.0131"/>
      </geometry>
    </collision>
    <visual>
      <origin xyz="-0.0144 -0.0102 0" rpy="0 0 0"/>
      <geometry>
        <box size="0.0023 0.0445 0.0077"/>
      </geometry>
    </visual>
    <collision>
      <origin xyz="-0.0144 -0.0102 0" rpy="0 0 0"/>
      <geometry>
        <box size="0.0023 0.0445 0.0077"/>
      </geometry>
    </collision>
  </link>
  <joint name="base_link_ir2_joint" type="fixed">
    <parent link="base_link"/>
    <child link="ir2"/>
    <origin xyz="0.1736 0.1454 0.0566" rpy="1.570797 0 0.756286"/>
  </joint>
  <link name="ir1">
    <visual>
      <origin xyz="-0.0052 -0.0102 0" rpy="0 0 0"/>
      <geometry>
        <box size="0.01 0.03 0.0087"/>
      </geometry>
    </visual>
    <collision>
      <origin xyz="-0.0052 -0.0102 0" rpy="0 0 0"/>
      <geometry>
        <box size="0.01 0.03 0.0087"/>
      </geometry>
    </collision>
    <visual>
      <origin xyz="-0.0109 -0.0102 0" rpy="0 0 0"/>
      <geometry>
        <box size="0.0094 0.03 0.0131"/>
      </geometry>
    </visual>
    <collision>
      <origin xyz="-0.0109 -0.0102 0" rpy="0 0 0"/>
      <geometry>
        <box size="0.0094 0.03 0.0131"/>
      </geometry>
    </collision>
    <visual>
      <origin xyz="-0.0144 -0.0102 0" rpy="0 0 0"/>
      <geometry>
        <box size="0.0023 0.0445 0.0077"/>
      </geometry>
    </visual>
    <collision>
      <origin xyz="-0.0144 -0.0102 0" rpy="0 0 0"/>
      <geometry>
        <box size="0.0023 0.0445 0.0077"/>
      </geometry>
    </collision>
  </link>
  <joint name="base_link_ir1_joint" type="fixed">
    <parent link="base_link"/>
    <child link="ir1"/>
    <origin xyz="0.2264 0 0.0566" rpy="1.570797 0.000001 -0.000123"/>
  </joint>
  <link name="compass">
  </link>
  <joint name="base_link_compass_joint" type="fixed">
    <parent link="base_link"/>
    <child link="compass"/>
    <origin xyz="0 0 0" rpy="0 0 1.570796"/>
  </joint>
  <link name="gyro">
  </link>
  <joint name="base_link_gyro_joint" type="fixed">
    <parent link="base_link"/>
    <child link="gyro"/>
    <origin xyz="0 0 0" rpy="0 0 1.570796"/>
  </joint>
  <link name="inertial unit">
  </link>
  <joint name="base_link_inertial unit_joint" type="fixed">
    <parent link="base_link"/>
    <child link="inertial unit"/>
    <origin xyz="0 0 0" rpy="0 0 1.570796"/>
  </joint>
  <link name="accelerometer">
  </link>
  <joint name="base_link_accelerometer_joint" type="fixed">
    <parent link="base_link"/>
    <child link="accelerometer"/>
    <origin xyz="0 0 0" rpy="0 0 1.570796"/>
  </joint>
  <link name="Hokuyo mounting support for Robotino 3">
    <visual>
      <origin xyz="-0.027 0.03 0.106" rpy="0 0 0"/>
      <geometry>
        <box size="0.055 0.06 0.002"/>
      </geometry>
    </visual>
    <collision>
      <origin xyz="-0.027 0.03 0.106" rpy="0 0 0"/>
      <geometry>
        <box size="0.055 0.06 0.002"/>
      </geometry>
    </collision>
    <visual>
      <origin xyz="-0.001 0.03 0.053" rpy="0 0 0"/>
      <geometry>
        <box size="0.0028 0.062 0.107"/>
      </geometry>
    </visual>
    <collision>
      <origin xyz="-0.001 0.03 0.053" rpy="0 0 0"/>
      <geometry>
        <box size="0.0028 0.062 0.107"/>
      </geometry>
    </collision>
  </link>
  <joint name="base_link_Hokuyo mounting support for Robotino 3_joint" type="fixed">
    <parent link="base_link"/>
    <child link="Hokuyo mounting support for Robotino 3"/>
    <origin xyz="0.0328 -0.03 0.2128" rpy="0 0 -0.000004"/>
  </joint>
  <link name="Hokuyo URG-04LX-UG01">
    <visual>
      <origin xyz="0 0 -0.018" rpy="1.570741 0.000118 -1.570741"/>
      <geometry>
        <box size="0.05 0.07 0.05"/>
      </geometry>
    </visual>
    <collision>
      <origin xyz="0 0 -0.018" rpy="1.570741 0.000118 -1.570741"/>
      <geometry>
        <box size="0.05 0.07 0.05"/>
      </geometry>
    </collision>
  </link>
  <joint name="Hokuyo mounting support for Robotino 3_Hokuyo URG-04LX-UG01_joint" type="fixed">
    <parent link="Hokuyo mounting support for Robotino 3"/>
    <child link="Hokuyo URG-04LX-UG01"/>
    <origin xyz="-0.028 0.03 0.16" rpy="0 0 0"/>
  </joint>
  <joint name="wheel2_joint" type="continuous">
    <parent link="base_link"/>
    <child link="wheel2_link"/>
    <axis xyz="0 1 0"/>
    <limit effort="10" velocity="137.46"/>
    <origin xyz="0.0913 0.158136 0.05915" rpy="0 0 -0.523599"/>
  </joint>
  <link name="wheel2_link">
    <visual>
      <origin xyz="0 0 0" rpy="-1.570796 0 0"/>
      <geometry>
        <mesh filename="package://rto_description/meshes/parts/robotino_wheel.dae" scale="0.01 0.01 0.01"/>
      </geometry>
    </visual>
    <collision>
      <origin xyz="0 0 0" rpy="-1.570796 0 0"/>
      <geometry>
        <cylinder radius="0.063" length="0.01"/>
      </geometry>
    </collision>
  </link>
  <joint name="wheel1_joint" type="continuous">
    <parent link="base_link"/>
    <child link="wheel1_link"/>
    <axis xyz="0 1 0"/>
    <limit effort="10" velocity="137.46"/>
    <origin xyz="0.0913 -0.158136 0.05915" rpy="0 0 -2.617994"/>
  </joint>
  <link name="wheel1_link">
    <visual>
      <origin xyz="0 0 0" rpy="-1.570796 0 0"/>
      <geometry>
        <mesh filename="package://rto_description/meshes/parts/robotino_wheel.dae" scale="0.01 0.01 0.01"/>
      </geometry>
    </visual>
    <collision>
      <origin xyz="0 0 0" rpy="-1.570796 0 0"/>
      <geometry>
        <cylinder radius="0.063" length="0.01"/>
      </geometry>
    </collision>
  </link>
  <joint name="wheel0_joint" type="continuous">
    <parent link="base_link"/>
    <child link="wheel0_link"/>
    <axis xyz="0 1 0"/>
    <limit effort="10" velocity="137.46"/>
    <origin xyz="-0.1826 0 0.05915" rpy="0 0 1.570796"/>
  </joint>
  <link name="wheel0_link">
    <visual>
      <origin xyz="0 0 0" rpy="-1.570796 0 0"/>
      <geometry>
        <mesh filename="package://rto_description/meshes/parts/robotino_wheel.dae" scale="0.01 0.01 0.01"/>
      </geometry>
    </visual>
    <collision>
      <origin xyz="0 0 0" rpy="-1.570796 0 0"/>
      <geometry>
        <cylinder radius="0.063" length="0.01"/>
      </geometry>
    </collision>
  </link>

<!-- Connect base_footprint to base_link -->
<link name="base_footprint"/>

<joint name="base_footprint_to_base_link" type="fixed">
  <parent link="base_footprint"/>
  <child link="base_link"/>
  <origin xyz="0 0 0" rpy="0 0 0"/>
</joint>

</robot>